<?xml version="1.0" encoding="utf-8"?>
<!-- This URDF was automatically created by SolidWorks to URDF Exporter! Originally created by Stephen Brawner (brawner@gmail.com) 
     Commit Version: 1.6.0-4-g7f85cfe  Build Version: 1.6.7995.38578
     For more information, please see http://wiki.ros.org/sw_urdf_exporter -->

<robot name="myrobot" xmlns:xacro="http://www.ros.org/wiki/xacro">

<xacro:include filename="$(find myrobot)/urdf/diffrobot.gazebo"/>

<link name="base_footprint">  
</link>

<joint name="base_footprint_joint" type="fixed">
      <origin
        xyz="0.0 0.0 0.0"
        rpy="0 0 0" />
    <parent link ="base_footprint"/>
    <child link ="base_link"/>   
</joint>

<link name="base_link">
    <inertial>
        <origin xyz="0.0 0.0 0.0" rpy="0.0 0.0 0.0"/>
        <mass value="3.0"/>
        <inertia ixx="0.0" ixy="0.0" ixz="0.0" iyy="0.0" iyz="0.0" izz="0.0"/>
    </inertial>
    <visual name="base_link_visual">
        <geometry>
           <cylinder radius="0.5" length="0.008"/>
        </geometry>
        <material name="">
            <color rgba="1.0 0.0 0.0 1.0"/>
            <texture filename=""/>
        </material>
    </visual>
    <collision>
        <origin xyz="0.0 0.0 0.0" rpy="0.0 0.0 0.0"/>
        <geometry>
           <cylinder radius="0.5" length="0.008"/>
        </geometry>
    </collision>
</link>





<link name="left_wheel">
    <inertial>
        <origin xyz="0.0 0.0 0.0" rpy="0.0 0.0 0.0"/>
        <mass value="1.0"/>
        <inertia ixx="1.0" ixy="0.0" ixz="0.0" iyy="1.0" iyz="0.0" izz="1.0"/>
    </inertial>
    <visual name="left_wheel_visual">
        <origin xyz="0.0 0.0 0.0" rpy="0.0 0.0 0.0"/>
        <geometry>
            <cylinder radius="0.085" length="0.032"/>
        </geometry>
        <material name="">
            <color rgba="0.0 0.0 1.0 1.0"/>
            <texture filename=""/>
        </material>
    </visual>
    <collision>
        <origin xyz="0.0 0.0 0.0" rpy="0.0 0.0 0.0"/>
        <geometry>
            <cylinder radius="0.085" length="0.032"/>
        </geometry>
    </collision>
</link>


<joint name="left_wheel_joint" type="continuous">
    <origin xyz="0.0 0.43 0.025" rpy="0.0 1.5707 1.5707"/>
    <parent link="base_link"/>
    <child link="left_wheel"/>
    <axis xyz="0.0 0.0 1.0"/>
    <limit lower="0.0" upper="0.0" effort="0.0" velocity="0.0"/>
</joint>



<link name="right_wheel">
    <inertial>
        <origin xyz="0.0 0.0 0.0" rpy="0.0 0.0 0.0"/>
        <mass value="1.0"/>
        <inertia ixx="1.0" ixy="0.0" ixz="0.0" iyy="1.0" iyz="0.0" izz="1.0"/>
    </inertial>
    <visual name="right_wheel_visual">
        <origin xyz="0.0 0.0 0.0" rpy="0.0 0.0 0.0"/>
        <geometry>
            <cylinder radius="0.085" length="0.032"/>
        </geometry>
        <material name="">
            <color rgba="0.0 0.0 1.0 1.0"/>
            <texture filename=""/>
        </material>
    </visual>
    <collision>
        <origin xyz="0.0 0.0 0.0" rpy="0.0 0.0 0.0"/>
        <geometry>
            <cylinder radius="0.085" length="0.032"/>
        </geometry>
    </collision>
</link>


<joint name="right_wheel_joint" type="continuous">
    <origin xyz="0.0 -0.43 0.025" rpy="0.0 1.5707 1.5707"/>
    <parent link="base_link"/>
    <child link="right_wheel"/>
    <axis xyz="0.0 0.0 1.0"/>
    <limit lower="0.0" upper="0.0" effort="0.0" velocity="0.0"/>
</joint>

<link name="front_caster">
    <inertial>
        <origin xyz="0.0 0.0 0.0" rpy="0.0 0.0 0.0"/>
        <mass value="0.2"/>
        <inertia ixx="0.0" ixy="0.0" ixz="0.0" iyy="0.0" iyz="0.0" izz="0.0"/>
    </inertial>
    <visual name="front_caster_visual">
        <origin xyz="0.0 0.0 0.0" rpy="0.0 0.0 0.0"/>
        <geometry>
             <sphere radius="0.043"/>
        </geometry>
        <material name="">
            <color rgba="1.0 1.0 0.0 1.0"/>
        </material>
    </visual>
    <collision>
        <origin xyz="0.0 0.0 0.0" rpy="0.0 0.0 0.0"/>
        <geometry>
             <sphere radius="0.043"/>
        </geometry>
    </collision>
</link>

<joint name="front_caster_joint" type="fixed">
    <origin xyz="0.35 0.0 -0.0170" rpy="0.0 1.5707 1.5707"/>
    <parent link="base_link"/>
    <child link="front_caster"/>
    <axis xyz="0.0 0.0 0.0"/>
    <limit lower="0.0" upper="0.0" effort="0.0" velocity="0.0"/>
</joint>


<link name="back_caster">
    <inertial>
        <origin xyz="0.0 0.0 0.0" rpy="0.0 0.0 0.0"/>
        <mass value="0.2"/>
        <inertia ixx="0.0" ixy="0.0" ixz="0.0" iyy="0.0" iyz="0.0" izz="0.0"/>
    </inertial>
    <visual name="back_caster_visual">
        <origin xyz="0.0 0.0 0.0" rpy="0.0 0.0 0.0"/>
        <geometry>
             <sphere radius="0.043"/>
        </geometry>
        <material name="">
            <color rgba="1.0 1.0 0.0 1.0"/>
        </material>
    </visual>
    <collision>
        <origin xyz="0.0 0.0 0.0" rpy="0.0 0.0 0.0"/>
        <geometry>
             <sphere radius="0.043"/>
        </geometry>
    </collision>
</link>

<joint name="back_caster_joint" type="fixed">
    <origin xyz="-0.35 0.0 -0.0170" rpy="0.0 1.5707 1.5707"/>
    <parent link="base_link"/>
    <child link="back_caster"/>
    <axis xyz="0.0 0.0 0.0"/>
    <limit lower="0.0" upper="0.0" effort="0.0" velocity="0.0"/>
</joint>

<link name="cover_link">
    <inertial>
        <origin xyz="0.0 0.0 -0.000001" rpy="0.0 0.0 0.0"/>
        <mass value="9.0"/>
        <inertia ixx="0.0" ixy="0.0" ixz="0.0" iyy="0.0" iyz="0.0" izz="0.0"/>
    </inertial>
    <visual name="cover_link_visual">
        <origin xyz="0.0 0.0 0.0" rpy="0.0 0.0 0.0"/>
        <geometry>
    <cylinder radius="0.5" length="0.24"/>
       </geometry>
        <material name="">
            <color rgba="1.0 0.0 0.0 1.0"/>
            <texture filename=""/>
        </material>
    </visual>
    <collision>
        <origin xyz="0.0 0.0 0.0" rpy="0.0 0.0 0.0"/>
        <geometry>
    <cylinder radius="0.5" length="0.24"/>
        </geometry>
    </collision>
</link>
<joint name="cover_joint" type="fixed">
    <origin xyz="0.0 0.0 0.122" rpy="0.0 0.0 0.0"/>
    <parent link="base_link"/>
    <child link="cover_link"/>
    <axis xyz="0.0 0.0 0.0"/>
    <limit lower="0.0" upper="0.0" effort="0.0" velocity="0.0"/>
</joint>


  <link name="lidar_link">
    <inertial>
        <origin xyz="0.0 0.0 0.0" rpy="0.0 0.0 0.0"/>
        <mass value="0.0"/>
        <inertia ixx="1.0" ixy="0.0" ixz="0.0" iyy="1.0" iyz="0.0" izz="1.0"/>
    </inertial>
    <visual name="lidar_link_visual">
        <origin xyz="0.0 0.0 0.0" rpy="0.0 0.0 0.0"/>
        <geometry>
       <mesh filename="package://myrobot/meshes/lidar_link.STL"/>     
          </geometry>
        <material name="">
            <color rgba="0.0 0.0 1.0 1.0"/>
            <texture filename=""/>
        </material>
    </visual>
    <collision>
        <origin xyz="0.0 0.0 0.0" rpy="0.0 0.0 0.0"/>
        <geometry>
       <mesh filename="package://myrobot/meshes/lidar_link.STL"/>     
        </geometry>
    </collision>
</link>

<joint name="lidar_joint" type="fixed">
 <origin xyz="0.4 0.092 0.1897" rpy="1.57079632679491 0.0 0.0"/>
  <parent link="base_link"/>
    <child link="lidar_link"/>
    <axis xyz="0.0 0.0 0.0"/>
    <limit lower="0.0" upper="0.0" effort="0.0" velocity="0.0"/>
</joint>
   
    <link name="laser_data_link">
        
    </link>

    <joint name="laser_data_joint" type="fixed">

        <origin xyz="-0.005 0.079 0.1" rpy="1.57079632679491 0.0 0.0"/> 
        <parent link="lidar_link"/>
        <child link="laser_data_link"/>

    </joint>

<link name="cylinder_link">
    <inertial>
        <origin xyz="0.0 0.0 0.0" rpy="0.0 0.0 0.0"/>
        <mass value="0.5"/>
        <inertia ixx="0.0" ixy="0.0" ixz="0.0" iyy="0.0" iyz="0.0" izz="0.0"/>
    </inertial>
    <visual name="cylinder_link_visual">
        <origin xyz="0.0 0.0 0.0" rpy="0.0 0.0 0.0"/>
        <geometry>
    <cylinder radius="0.04" length="0.48"/>
        </geometry>
        <material name="">
            <color rgba="1.0 1.0 0.0 1.0"/>
            <texture filename=""/>
        </material>
    </visual>
    <collision>
        <origin xyz="0.0 0.0 0.0" rpy="0.0 0.0 0.0"/>
        <geometry>
    <cylinder radius="0.04" length="0.44"/>
        </geometry>
    </collision>
</link>
<joint name="cylinder_joint" type="fixed">
    <origin xyz="0.0 0.0 0.34" rpy="0.0 0.0 0.0"/>
    <parent link="cover_link"/>
    <child link="cylinder_link"/>
    <axis xyz="0.0 0.0 0.0"/>
    <limit lower="0.0" upper="0.0" effort="0.0" velocity="0.0"/>
</joint>


<link name="camera_link">
    <inertial>
        <origin xyz="0.0 0.0 0.0" rpy="0.0 0.0 0.0"/>
        <mass value="0.01"/>
        <inertia ixx="0.0" ixy="0.0" ixz="0.0" iyy="0.0" iyz="0.0" izz="0.0"/>
    </inertial>
    <visual name="camera_link_visual">
        <origin xyz="0.0 0.0 0.0" rpy="0.0 0.0 0.0"/>
        <geometry>
           <mesh filename="package://myrobot/meshes/kinect.dae"/>  
        </geometry>
        <material name="">
            <color rgba="1.0 0.0 0.0 1.0"/>
            <texture filename=""/>
        </material>
    </visual>
    <collision>
        <origin xyz="0.0 0.0 0.0" rpy="0.0 0.0 0.0"/>
        <geometry>
           <mesh filename="package://myrobot/meshes/kinect.dae"/>  
          </geometry>
    </collision>
</link>

<joint name="camera_joint" type="fixed">
    <origin xyz="0.0 0.0 0.275" rpy="0.0 0.0 1.57"/>
    <parent link="cylinder_link"/>
    <child link="camera_link"/>
    <axis xyz="0.0 0.0 0.0"/>
    <limit lower="0.0" upper="0.0" effort="0.0" velocity="0.0"/>
</joint>

  <link name="camera_link_optical">
    
  </link>
    <joint name="camera_optical_joint" type="fixed">
          <parent link="camera_link"/>
          <child link="camera_link_optical"/>
          <origin xyz="0 0 0" rpy="0.0 0.0 0.0"/>
      </joint>  

      <link name="imu_link">
        <collision>
           <origin xyz="0 0 0.0" rpy="0 0 0"/>
           <geometry>
           <box size="0.0 0.0 0.0"/>
           </geometry>
        </collision>
        <visual>
           <origin xyz="0 0 0.1" rpy="0 0 0"/>
           <geometry>
           <box size="0.0 0.0 0.0"/>
           </geometry>
           <material name=""/>
        </visual>
        <inertial>
           <origin xyz="0 0 0" rpy="0 0 0"/>
           <mass value="0.00001"/>
           <inertia ixx="1.0" ixy="0.0" ixz="0.0" iyy="1.0" iyz="0.0" izz="1.0"/>
        </inertial>
       </link>
       <joint name="imu_joint" type="fixed">
           <origin xyz="0.0 0.0 0.0" rpy="0.0 0.0 0.0"/>
           <parent link="base_link"/>
           <child link="imu_link"/>
       </joint>
</robot>

  


   
  
